Workbook

Sheet Summary — Path to $1M
A1: JHBI DS Apps — Path to $1M ARR
A2: Combined JHBI ARR: DS Apps + Platform Migration Uplift (JHAKnow + ARCU → JHBI). Milestone: Q4 FY27 combined. All values from Revenue Model.
A4: QUARTERLY ARR SUMMARY
A5: Quarter | B5: Calendar | C5: Zelle Memo ARR | D5: Churn Sentinel ARR | E5: CommercialSignal ARR | F5: Gen. Wealth ARR | G5: Anomaly ARR | H5: Platform Migration ARR | I5: Total JHBI ARR
A6: Q3 FY26 | B6: Jan–Mar 2026 | C6: ='Revenue Model'!C8 | D6: ='Revenue Model'!C13 | E6: ='Revenue Model'!C18 | F6: ='Revenue Model'!C23 | G6: ='Revenue Model'!C28 | H6: ='Revenue Model'!C33 | I6: ='Revenue Model'!C37
A7: Q4 FY26 | B7: Apr–Jun 2026 | C7: ='Revenue Model'!D8 | D7: ='Revenue Model'!D13 | E7: ='Revenue Model'!D18 | F7: ='Revenue Model'!D23 | G7: ='Revenue Model'!D28 | H7: ='Revenue Model'!D33 | I7: ='Revenue Model'!D37
A8: Q1 FY27 | B8: Jul–Sep 2026 | C8: ='Revenue Model'!E8 | D8: ='Revenue Model'!E13 | E8: ='Revenue Model'!E18 | F8: ='Revenue Model'!E23 | G8: ='Revenue Model'!E28 | H8: ='Revenue Model'!E33 | I8: ='Revenue Model'!E37
A9: Q2 FY27 | B9: Oct–Dec 2026 | C9: ='Revenue Model'!F8 | D9: ='Revenue Model'!F13 | E9: ='Revenue Model'!F18 | F9: ='Revenue Model'!F23 | G9: ='Revenue Model'!F28 | H9: ='Revenue Model'!F33 | I9: ='Revenue Model'!F37
A10: Q3 FY27 | B10: Jan–Mar 2027 | C10: ='Revenue Model'!G8 | D10: ='Revenue Model'!G13 | E10: ='Revenue Model'!G18 | F10: ='Revenue Model'!G23 | G10: ='Revenue Model'!G28 | H10: ='Revenue Model'!G33 | I10: ='Revenue Model'!G37
A11: Q4 FY27 | B11: Apr–Jun 2027 | C11: ='Revenue Model'!H8 | D11: ='Revenue Model'!H13 | E11: ='Revenue Model'!H18 | F11: ='Revenue Model'!H23 | G11: ='Revenue Model'!H28 | H11: ='Revenue Model'!H33 | I11: ='Revenue Model'!H37
A12: Q1 FY28 | B12: Jul–Sep 2027 | C12: ='Revenue Model'!I8 | D12: ='Revenue Model'!I13 | E12: ='Revenue Model'!I18 | F12: ='Revenue Model'!I23 | G12: ='Revenue Model'!I28 | H12: ='Revenue Model'!I33 | I12: ='Revenue Model'!I37
A13: Q2 FY28 | B13: Oct–Dec 2027 | C13: ='Revenue Model'!J8 | D13: ='Revenue Model'!J13 | E13: ='Revenue Model'!J18 | F13: ='Revenue Model'!J23 | G13: ='Revenue Model'!J28 | H13: ='Revenue Model'!J33 | I13: ='Revenue Model'!J37
A14: ★ Combined JHBI ARR (DS Apps + Migration) crosses $1M in Q4 FY27 (Apr–Jun 2027) | DS Apps alone: $1M in Q1 FY28 | Migration: 10% uplift placeholder on 300 JHAKnow/ARCU FIs
A16: KEY ASSUMPTIONS DRIVING THE MODEL
A17: Total JH Addressable FIs | E17: 1,660 | F17: Contracted core banking FIs (44% CU / 56% Bank)
A18: CU Share | E18: 44% | F18: Symitar / credit union base
A19: CU Discount | E19: 12% | F19: Cooperative budget accommodation
A20: Zelle Penetration | E20: 15.7% | F20: 260 of ~1,660 JH core FIs currently Zelle-enabled
A21: Annual DS App Churn | E21: 8% | F21: FI churn on DS app subscriptions (2% quarterly)
A22: Migration FIs (JHAKnow + ARCU) | E22: 300 | F22: 150 bank (JHAKnow) + 150 CU (ARCU); nominal uplift placeholder
A23: Platform Uplift % | E23: 10% | F23: Placeholder — not finalized; adjust in Section 6 of Assumptions
A24: ★ Combined $1M Milestone | E24: Q4 FY27 | F24: DS Apps ($910K) + Platform Migration ($282K) = $1.19M ARR
A25: DS Apps Alone $1M Milestone | E25: Q1 FY28 | F25: $1.25M ARR from 4 apps, 102 active FI subscriptions, 6.1% penetration

Sheet Assumptions
A1: JHBI Revenue Model — Assumptions & Inputs
A2: ■ Blue = Hardcoded input (editable) ■ Black = Formula ■ Yellow bg = Key assumption
A4: SECTION 1 — MARKET PARAMETERS
A5: Total Addressable FIs (JH Core) | B5: 1660 | G5: JH ~1,660 contracted core banking FIs (banks + CUs)
A6: CU Share of Base | B6: 0.44 | G6: Est. Symitar/CU share; internal estimate
A7: Bank Share of Base | B7: =1-B6 | G7: Complement of CU share (formula-driven)
A8: CU Discount Rate | B8: 0.12 | G8: Pricing accommodation for cooperative/NCUA budget cycles
A9: Zelle Penetration (% of FIs) | B9: 0.157 | G9: 260 of ~1,660 JH core FIs currently Zelle-enabled via JHA PayCenter
A10: Annual Subscription Churn Rate | B10: 0.08 | G10: Annual FI churn on DS app subscriptions; adjust as needed
A12: SECTION 2 — FI BASE BY ASSET TIER
A13: Asset Tier | B13: Total FIs | C13: CU | D13: Bank | E13: Zelle-Enabled | G13: Notes
A14: <$250M | B14: 500 | C14: =ROUND(B14*$B$6,0) | D14: =B14-C14 | E14: =ROUND(B14*$B$9,0)
A15: $250M–$1B | B15: 800 | C15: =ROUND(B15*$B$6,0) | D15: =B15-C15 | E15: =ROUND(B15*$B$9,0)
A16: $1B–$5B | B16: 280 | C16: =ROUND(B16*$B$6,0) | D16: =B16-C16 | E16: =ROUND(B16*$B$9,0)
A17: $5B+ | B17: 80 | C17: =ROUND(B17*$B$6,0) | D17: =B17-C17 | E17: =ROUND(B17*$B$9,0)
A18: TOTAL | B18: =SUM(B14:B17) | C18: =SUM(C14:C17) | D18: =SUM(D14:D17) | E18: =SUM(E14:E17)
A20: SECTION 3 — DS APP PRICING (Annual per FI, add-on to JHBI platform)
A21: App | B21: <$250M (Bank) | C21: $250M–$1B (Bank) | D21: $1B–$5B (Bank) | E21: $5B+ (Bank) | G21: Notes
A22: Zelle Memo Intelligence | B22: 5000 | C22: 8000 | D22: 15000 | E22: 25000 | G22: Zelle-enabled FIs only (260 currently; ~15.7% of base)
A23: Churn Sentinel | B23: 8000 | C23: 12000 | D23: 22000 | E23: 35000 | G23: Universal — all FI types, all tiers
A24: CommercialSignal | B24: 6000 | C24: 10000 | D24: 18000 | E24: 28000 | G24: Universal — runs on ACH/payments data
A25: Gen. Wealth Deflection | B25: 8000 | C25: 12000 | D25: 20000 | E25: 30000 | G25: Universal — requires core + household data (Phase 3)
A26: Anomaly Detection | B26: 8000 | C26: 15000 | D26: 25000 | E26: 40000 | G26: Universal — real-time streaming (Phase 3)
A28: SECTION 4 — CU EFFECTIVE PRICING (Bank rate × (1 − CU Discount))
A29: App | B29: <$250M (CU) | C29: $250M–$1B (CU) | D29: $1B–$5B (CU) | E29: $5B+ (CU)
A30: =Assumptions!A22 | B30: =Assumptions!B22*(1-$B$7) | C30: =Assumptions!C22*(1-$B$7) | D30: =Assumptions!D22*(1-$B$7) | E30: =Assumptions!E22*(1-$B$7)
A31: =Assumptions!A23 | B31: =Assumptions!B23*(1-$B$7) | C31: =Assumptions!C23*(1-$B$7) | D31: =Assumptions!D23*(1-$B$7) | E31: =Assumptions!E23*(1-$B$7)
A32: =Assumptions!A24 | B32: =Assumptions!B24*(1-$B$7) | C32: =Assumptions!C24*(1-$B$7) | D32: =Assumptions!D24*(1-$B$7) | E32: =Assumptions!E24*(1-$B$7)
A33: =Assumptions!A25 | B33: =Assumptions!B25*(1-$B$7) | C33: =Assumptions!C25*(1-$B$7) | D33: =Assumptions!D25*(1-$B$7) | E33: =Assumptions!E25*(1-$B$7)
A34: =Assumptions!A26 | B34: =Assumptions!B26*(1-$B$7) | C34: =Assumptions!C26*(1-$B$7) | D34: =Assumptions!D26*(1-$B$7) | E34: =Assumptions!E26*(1-$B$7)
A36: SECTION 5 — BLENDED AVG SUBSCRIPTION PRICE (Weighted by adoption tier mix, CU/Bank split)
A37: Used in Revenue Model sheet. Weighted average accounts for tier mix of signing FIs and CU discount applied proportionally.
A38: App | B38: Blended Avg Price / FI | C38: Annual FI Target | D38: Year 1 ARR Potential | G38: Source / Notes
A39: Zelle Memo Intelligence | B39: 9700 | C39: 40 | D39: =B39*C39 | G39: Tier mix: 20%/<$250M, 50%/$250M-1B, 22.5%/$1B-5B, 7.5%/$5B+; CU share blended
A40: Churn Sentinel | B40: 13700 | C40: 50 | D40: =B40*C40 | G40: Broader tier reach; higher avg due to $1B+ FI interest
A41: CommercialSignal | B41: 11100 | C41: 35 | D41: =B41*C41 | G41: Payments data only; moderate tier skew
A42: Gen. Wealth Deflection | B42: 13600 | C42: 24 | D42: =B42*C42 | G42: Core data dependency limits early adoption to mid/large tiers
A43: Anomaly Detection | B43: 16800 | C43: 24 | D43: =B43*C43 | G43: Highest price; complex streaming model; targets Tier 3-4
A44: TOTAL — Year 1 ARR Potential (all apps launched) | C44: =SUM(C39:C43) | D44: =SUM(D39:D43)
A46: SECTION 6 — JHBI PLATFORM MIGRATION UPLIFT (JHAKnow + ARCU → JHBI)
...

Sheet Revenue Model
A1: JHBI DS Apps — Quarterly ARR Build | Path to $1M
A2: ARR = Cumulative Active FIs × Annual Subscription Price. Churn applied quarterly (Annual Rate ÷ 4). All inputs in blue; formulas in black.
A3: Metric | B3: App | C3: Q3 FY26 | D3: Q4 FY26 | E3: Q1 FY27 | F3: Q2 FY27 | G3: Q3 FY27 | H3: Q4 FY27 | I3: Q1 FY28 | J3: Q2 FY28
C4: Jan–Mar 2026 | D4: Apr–Jun 2026 | E4: Jul–Sep 2026 | F4: Oct–Dec 2026 | G4: Jan–Mar 2027 | H4: Apr–Jun 2027 | I4: Jul–Sep 2027 | J4: Oct–Dec 2027
A5: Zelle Memo Intelligence
A6: New FIs Signed | B6: # | C6: 0 | D6: 0 | E6: 5 | F6: 4 | G6: 4 | H6: 4 | I6: 3 | J6: 3
A7: Active FIs (Cumul., net churn) | B7: # | C7: =ROUND(C6,0) | D7: =ROUND(C7*(1-Assumptions!$B$10/4)+D6,0) | E7: =ROUND(D7*(1-Assumptions!$B$10/4)+E6,0) | F7: =ROUND(E7*(1-Assumptions!$B$10/4)+F6,0) | G7: =ROUND(F7*(1-Assumptions!$B$10/4)+G6,0) | H7: =ROUND(G7*(1-Assumptions!$B$10/4)+H6,0) | I7: =ROUND(H7*(1-Assumptions!$B$10/4)+I6,0) | J7: =ROUND(I7*(1-Assumptions!$B$10/4)+J6,0)
A8: Ending ARR | B8: $ | C8: =ROUND(C7*Assumptions!$B$39,0) | D8: =ROUND(D7*Assumptions!$B$39,0) | E8: =ROUND(E7*Assumptions!$B$39,0) | F8: =ROUND(F7*Assumptions!$B$39,0) | G8: =ROUND(G7*Assumptions!$B$39,0) | H8: =ROUND(H7*Assumptions!$B$39,0) | I8: =ROUND(I7*Assumptions!$B$39,0) | J8: =ROUND(J7*Assumptions!$B$39,0)
A10: Churn Sentinel
A11: New FIs Signed | B11: # | C11: 0 | D11: 0 | E11: 0 | F11: 15 | G11: 13 | H11: 12 | I11: 10 | J11: 8
A12: Active FIs (Cumul., net churn) | B12: # | C12: =ROUND(C11,0) | D12: =ROUND(C12*(1-Assumptions!$B$10/4)+D11,0) | E12: =ROUND(D12*(1-Assumptions!$B$10/4)+E11,0) | F12: =ROUND(E12*(1-Assumptions!$B$10/4)+F11,0) | G12: =ROUND(F12*(1-Assumptions!$B$10/4)+G11,0) | H12: =ROUND(G12*(1-Assumptions!$B$10/4)+H11,0) | I12: =ROUND(H12*(1-Assumptions!$B$10/4)+I11,0) | J12: =ROUND(I12*(1-Assumptions!$B$10/4)+J11,0)
A13: Ending ARR | B13: $ | C13: =ROUND(C12*Assumptions!$B$40,0) | D13: =ROUND(D12*Assumptions!$B$40,0) | E13: =ROUND(E12*Assumptions!$B$40,0) | F13: =ROUND(F12*Assumptions!$B$40,0) | G13: =ROUND(G12*Assumptions!$B$40,0) | H13: =ROUND(H12*Assumptions!$B$40,0) | I13: =ROUND(I12*Assumptions!$B$40,0) | J13: =ROUND(J12*Assumptions!$B$40,0)
A15: CommercialSignal
A16: New FIs Signed | B16: # | C16: 0 | D16: 0 | E16: 0 | F16: 0 | G16: 10 | H16: 9 | I16: 8 | J16: 7
A17: Active FIs (Cumul., net churn) | B17: # | C17: =ROUND(C16,0) | D17: =ROUND(C17*(1-Assumptions!$B$10/4)+D16,0) | E17: =ROUND(D17*(1-Assumptions!$B$10/4)+E16,0) | F17: =ROUND(E17*(1-Assumptions!$B$10/4)+F16,0) | G17: =ROUND(F17*(1-Assumptions!$B$10/4)+G16,0) | H17: =ROUND(G17*(1-Assumptions!$B$10/4)+H16,0) | I17: =ROUND(H17*(1-Assumptions!$B$10/4)+I16,0) | J17: =ROUND(I17*(1-Assumptions!$B$10/4)+J16,0)
A18: Ending ARR | B18: $ | C18: =ROUND(C17*Assumptions!$B$41,0) | D18: =ROUND(D17*Assumptions!$B$41,0) | E18: =ROUND(E17*Assumptions!$B$41,0) | F18: =ROUND(F17*Assumptions!$B$41,0) | G18: =ROUND(G17*Assumptions!$B$41,0) | H18: =ROUND(H17*Assumptions!$B$41,0) | I18: =ROUND(I17*Assumptions!$B$41,0) | J18: =ROUND(J17*Assumptions!$B$41,0)
A20: Gen. Wealth Deflection
A21: New FIs Signed | B21: # | C21: 0 | D21: 0 | E21: 0 | F21: 0 | G21: 0 | H21: 0 | I21: 7 | J21: 6
A22: Active FIs (Cumul., net churn) | B22: # | C22: =ROUND(C21,0) | D22: =ROUND(C22*(1-Assumptions!$B$10/4)+D21,0) | E22: =ROUND(D22*(1-Assumptions!$B$10/4)+E21,0) | F22: =ROUND(E22*(1-Assumptions!$B$10/4)+F21,0) | G22: =ROUND(F22*(1-Assumptions!$B$10/4)+G21,0) | H22: =ROUND(G22*(1-Assumptions!$B$10/4)+H21,0) | I22: =ROUND(H22*(1-Assumptions!$B$10/4)+I21,0) | J22: =ROUND(I22*(1-Assumptions!$B$10/4)+J21,0)
A23: Ending ARR | B23: $ | C23: =ROUND(C22*Assumptions!$B$42,0) | D23: =ROUND(D22*Assumptions!$B$42,0) | E23: =ROUND(E22*Assumptions!$B$42,0) | F23: =ROUND(F22*Assumptions!$B$42,0) | G23: =ROUND(G22*Assumptions!$B$42,0) | H23: =ROUND(H22*Assumptions!$B$42,0) | I23: =ROUND(I22*Assumptions!$B$42,0) | J23: =ROUND(J22*Assumptions!$B$42,0)
A25: Anomaly Detection
A26: New FIs Signed | B26: # | C26: 0 | D26: 0 | E26: 0 | F26: 0 | G26: 0 | H26: 0 | I26: 0 | J26: 7
A27: Active FIs (Cumul., net churn) | B27: # | C27: =ROUND(C26,0) | D27: =ROUND(C27*(1-Assumptions!$B$10/4)+D26,0) | E27: =ROUND(D27*(1-Assumptions!$B$10/4)+E26,0) | F27: =ROUND(E27*(1-Assumptions!$B$10/4)+F26,0) | G27: =ROUND(F27*(1-Assumptions!$B$10/4)+G26,0) | H27: =ROUND(G27*(1-Assumptions!$B$10/4)+H26,0) | I27: =ROUND(H27*(1-Assumptions!$B$10/4)+I26,0) | J27: =ROUND(I27*(1-Assumptions!$B$10/4)+J26,0)
A28: Ending ARR | B28: $ | C28: =ROUND(C27*Assumptions!$B$43,0) | D28: =ROUND(D27*Assumptions!$B$43,0) | E28: =ROUND(E27*Assumptions!$B$43,0) | F28: =ROUND(F27*Assumptions!$B$43,0) | G28: =ROUND(G27*Assumptions!$B$43,0) | H28: =ROUND(H27*Assumptions!$B$43,0) | I28: =ROUND(I27*Assumptions!$B$43,0) | J28: =ROUND(J27*Assumptions!$B$43,0)
A30: JHBI PLATFORM MIGRATION UPLIFT — JHAKnow + ARCU → JHBI (Nominal Upcharge)
A31: Cumul. Bank FIs Migrated (JHAKnow → JHBI) | B31: # | C31: 0 | D31: 0 | E31: 20 | F31: 75 | G31: 120 | H31: 150 | I31: 150 | J31: 150
A32: Cumul. CU FIs Migrated (ARCU → JHBI) | B32: # | C32: 0 | D32: 0 | E32: 20 | F32: 75 | G32: 120 | H32: 150 | I32: 150 | J32: 150
A33: Platform Migration Upcharge ARR | B33: $ | C33: =ROUND(C31*Assumptions!$B$52+C32*Assumptions!$B$53,0) | D33: =ROUND(D31*Assumptions!$B$52+D32*Assumptions!$B$53,0) | E33: =ROUND(E31*Assumptions!$B$52+E32*Assumptions!$B$53,0) | F33: =ROUND(F31*Assumptions!$B$52+F32*Assumptions!$B$53,0) | G33: =ROUND(G31*Assumptions!$B$52+G32*Assumptions!$B$53,0) | H33: =ROUND(H31*Assumptions!$B$52+H32*Assumptions!$B$53,0) | I33: =ROUND(I31*Assumptions!$B$52+I32*Assumptions!$B$53,0) | J33: =ROUND(J31*Assumptions!$B$52+J32*Assumptions!$B$53,0)
A35: TOTAL — COMBINED JHBI ARR (DS Apps + Platform Migration Uplift)
A36: Total Active FI App Subscriptions | B36: # | C36: =C7+C12+C17+C22+C27 | D36: =D7+D12+D17+D22+D27 | E36: =E7+E12+E17+E22+E27 | F36: =F7+F12+F17+F22+F27 | G36: =G7+G12+G17+G22+G27 | H36: =H7+H12+H17+H22+H27 | I36: =I7+I12+I17+I22+I27 | J36: =J7+J12+J17+J22+J27
A37: TOTAL ARR | B37: $ | C37: =C8+C13+C18+C23+C28+C33 | D37: =D8+D13+D18+D23+D28+D33 | E37: =E8+E13+E18+E23+E28+E33 | F37: =F8+F13+F18+F23+F28+F33 | G37: =G8+G13+G18+G23+G28+G33 | H37: =H8+H13+H18+H23+H28+H33 | I37: =I8+I13+I18+I23+I28+I33 | J37: =J8+J13+J18+J23+J28+J33
A38: QoQ ARR Growth | B38: % | C38: "-" | D38: =IF(C37=0,"-",(D37-C37)/C37) | E38: =IF(D37=0,"-",(E37-D37)/D37) | F38: =IF(E37=0,"-",(F37-E37)/E37) | G38: =IF(F37=0,"-",(G37-F37)/F37) | H38: =IF(G37=0,"-",(H37-G37)/G37) | I38: =IF(H37=0,"-",(I37-H37)/H37) | J38: =IF(I37=0,"-",(J37-I37)/I37)
A39: $1M ARR Milestone | B39: ✓ | C39: =IF(C37>=1000000,"✓ $1M","—") | D39: =IF(D37>=1000000,"✓ $1M","—") | E39: =IF(E37>=1000000,"✓ $1M","—") | F39: =IF(F37>=1000000,"✓ $1M","—") | G39: =IF(G37>=1000000,"✓ $1M","—") | H39: =IF(H37>=1000000,"✓ $1M","—") | I39: =IF(I37>=1000000,"✓ $1M","—") | J39: =IF(J37>=1000000,"✓ $1M","—")
